<?xml version="1.0" encoding="utf-8"?>

<robot xmlns:xacro="http://www.ros.org/wiki/xacro" name="$(arg robot_name)">  
  <xacro:arg name="robot_name" default="robot"/>  
  <!-- Robot Footprint -->  
  <link name="$(arg robot_name)_base_footprint"/>  
  <!-- base link -->  
  <link name="$(arg robot_name)_base_link"> 
    <visual> 
      <origin xyz="0 0 0.0" rpy="0 0 0"/>  
      <geometry> 
        <cylinder length="0.12" radius="0.10"/> 
      </geometry>  
      <material name="blue"> 
        <color rgba="0.1 0.1 1.0 0.5"/> 
      </material> 
    </visual>  
    <collision> 
      <origin xyz="0 0 0.0" rpy="0 0 0"/>  
      <geometry> 
        <cylinder length="0.12" radius="0.10"/> 
      </geometry>  
      <material name="blue"> 
        <color rgba="0.1 0.1 1.0 0.5"/> 
      </material> 
    </collision>  
    <inertial> 
      <mass value="0.2"/>  
      <inertia ixx="0.0122666" ixy="0" ixz="0" iyy="0.0122666" iyz="0" izz="0.02"/> 
    </inertial> 
  </link>  
  <!-- base joint -->  
  <joint name="$(arg robot_name)_base_joint" type="fixed"> 
    <parent link="$(arg robot_name)_base_footprint"/>  
    <child link="$(arg robot_name)_base_link"/>  
    <origin xyz="0.0 0.0 0.076" rpy="0 0 0"/> 
  </joint>  
  <!-- laser link -->  
  <link name="$(arg robot_name)_laser_link"> 
    <visual> 
      <origin xyz="0 0 0" rpy="0 0 0"/>  
      <geometry> 
        <cylinder length="0.02" radius="0.02"/> 
      </geometry>  
      <material name="black"> 
        <color rgba="0.0 0.0 0.0 0.5"/> 
      </material> 
    </visual>  
    <collision> 
      <origin xyz="0 0 0" rpy="0 0 0"/>  
      <geometry> 
        <cylinder length="0.02" radius="0.02"/> 
      </geometry>  
      <material name="black"> 
        <color rgba="0.0 0.0 0.0 0.5"/> 
      </material> 
    </collision>  
    <inertial> 
      <mass value="0.1"/>  
      <inertia ixx="0.000190416666667" ixy="0" ixz="0" iyy="0.0001904" iyz="0" izz="0.00036"/> 
    </inertial> 
  </link>  
  <!-- laser joint -->  
  <joint name="$(arg robot_name)_laser_joint" type="fixed"> 
    <parent link="$(arg robot_name)_base_link"/>  
    <child link="$(arg robot_name)_laser_link"/>  
    <origin xyz="0 0 0.075"/> 
  </joint>  
  <!-- imu link -->  
  <link name="$(arg robot_name)_imu_link"> 
    <visual> 
      <origin xyz="0 0 0.0" rpy="0 0 0"/>  
      <geometry> 
        <box size="0.02 0.02 0.02"/> 
      </geometry> 
    </visual>  
    <collision> 
      <origin xyz="0 0 0.0" rpy="0 0 0"/>  
      <geometry> 
        <box size="0.02 0.02 0.02"/> 
      </geometry> 
    </collision>  
    <inertial> 
      <mass value="0.1"/>  
      <inertia ixx="0.000190416666667" ixy="0" ixz="0" iyy="0.0001904" iyz="0" izz="0.00036"/> 
    </inertial> 
  </link>  
  <!-- imu joint -->  
  <joint name="$(arg robot_name)_imu_joint" type="fixed"> 
    <parent link="$(arg robot_name)_base_link"/>  
    <child link="$(arg robot_name)_imu_link"/>  
    <origin xyz="0 0 0.02"/> 
  </joint>  
  <!-- left_wheel link -->  
  <link name="$(arg robot_name)_left_wheel_link"> 
    <visual> 
      <origin xyz="0 0 0" rpy="1.57079 0 0"/>  
      <geometry> 
        <cylinder length="0.04" radius="0.032"/> 
      </geometry>  
      <material name="black"> 
        <color rgba="0.0 0.0 0.0 0.5"/> 
      </material> 
    </visual>  
    <collision> 
      <origin xyz="0 0 0" rpy="1.57079 0 0"/>  
      <geometry> 
        <cylinder length="0.04" radius="0.032"/> 
      </geometry>  
      <material name="black"> 
        <color rgba="0.0 0.0 0.0 0.5"/> 
      </material> 
    </collision>  
    <inertial> 
      <mass value="0.2"/>  
      <inertia ixx="0.000190416666667" ixy="0" ixz="0" iyy="0.0001904" iyz="0" izz="0.00036"/> 
    </inertial> 
  </link>  
  <!-- left_wheel joint -->  
  <joint name="$(arg robot_name)_left_wheel_joint" type="continuous"> 
    <parent link="$(arg robot_name)_base_link"/>  
    <child link="$(arg robot_name)_left_wheel_link"/>  
    <origin xyz="-0.02 0.10 -0.06"/>  
    <axis xyz="0 1 0"/> 
  </joint>  
  <!-- right_wheel link -->  
  <link name="$(arg robot_name)_right_wheel_link"> 
    <visual> 
      <origin xyz="0 0 0" rpy="1.57079 0 0"/>  
      <geometry> 
        <cylinder length="0.04" radius="0.032"/> 
      </geometry>  
      <material name="black"> 
        <color rgba="0.0 0.0 0.0 0.5"/> 
      </material> 
    </visual>  
    <collision> 
      <origin xyz="0 0 0" rpy="1.57079 0 0"/>  
      <geometry> 
        <cylinder length="0.04" radius="0.032"/> 
      </geometry>  
      <material name="black"> 
        <color rgba="0.0 0.0 0.0 0.5"/> 
      </material> 
    </collision>  
    <inertial> 
      <mass value="0.2"/>  
      <inertia ixx="0.000190416666667" ixy="0" ixz="0" iyy="0.0001904" iyz="0" izz="0.00036"/> 
    </inertial> 
  </link>  
  <!-- right_wheel joint -->  
  <joint name="$(arg robot_name)_right_wheel_joint" type="continuous"> 
    <parent link="$(arg robot_name)_base_link"/>  
    <child link="$(arg robot_name)_right_wheel_link"/>  
    <origin xyz="-0.02 -0.10 -0.06"/>  
    <axis xyz="0 1 0"/> 
  </joint>  
  <!-- fornt caster link -->  
  <link name="$(arg robot_name)_front_caster_link"> 
    <visual> 
      <origin xyz="0 0 0" rpy="1.57079 0 0"/>  
      <geometry> 
        <sphere radius="0.016"/> 
      </geometry>  
      <material name="black"> 
        <color rgba="0.0 0.0 0.0 0.5"/> 
      </material> 
    </visual>  
    <collision> 
      <origin xyz="0 0 0" rpy="1.57079 0 0"/>  
      <geometry> 
        <sphere radius="0.016"/> 
      </geometry>  
      <material name="black"> 
        <color rgba="0.0 0.0 0.0 0.5"/> 
      </material> 
    </collision>  
    <inertial> 
      <mass value="0.02"/>  
      <inertia ixx="0.000190416666667" ixy="0" ixz="0" iyy="0.0001904" iyz="0" izz="0.00036"/> 
    </inertial> 
  </link>  
  <!-- front caster joint -->  
  <joint name="$(arg robot_name)_front_caster_joint" type="fixed"> 
    <parent link="$(arg robot_name)_base_link"/>  
    <child link="$(arg robot_name)_front_caster_link"/>  
    <origin xyz="0.06 0.0 -0.076"/>  
    <axis xyz="0 1 0"/> 
  </joint>  
  <gazebo reference="$(arg robot_name)_front_caster_link"> 
    <material>Gazebo/Black</material> 
  </gazebo>  
  <gazebo reference="$(arg robot_name)_front_caster_link"> 
    <mu1 value="0.0"/>  
    <mu2 value="0.0"/>  
    <kp value="1000000.0"/>  
    <kd value="10.0"/> 
  </gazebo>  
  <!-- after caster link -->  
  <link name="$(arg robot_name)_after_caster_link"> 
    <visual> 
      <origin xyz="0 0 0" rpy="1.57079 0 0"/>  
      <geometry> 
        <sphere radius="0.016"/> 
      </geometry>  
      <material name="black"> 
        <color rgba="0.0 0.0 0.0 0.5"/> 
      </material> 
    </visual>  
    <collision> 
      <origin xyz="0 0 0" rpy="1.57079 0 0"/>  
      <geometry> 
        <sphere radius="0.016"/> 
      </geometry>  
      <material name="black"> 
        <color rgba="0.0 0.0 0.0 0.5"/> 
      </material> 
    </collision>  
    <inertial> 
      <mass value="0.02"/>  
      <inertia ixx="0.000190416666667" ixy="0" ixz="0" iyy="0.0001904" iyz="0" izz="0.00036"/> 
    </inertial> 
  </link>  
  <!-- after caster joint -->  
  <joint name="$(arg robot_name)_after_caster_joint" type="fixed"> 
    <parent link="$(arg robot_name)_base_link"/>  
    <child link="$(arg robot_name)_after_caster_link"/>  
    <origin xyz="-0.06 0.0 -0.076"/>  
    <axis xyz="0 1 0"/> 
  </joint>  
  <gazebo reference="$(arg robot_name)_after_caster_link"> 
    <material>Gazebo/Black</material> 
  </gazebo>  
  <gazebo reference="$(arg robot_name)_after_caster_link"> 
    <mu1 value="0.0"/>  
    <mu2 value="0.0"/>  
    <kp value="1000000.0"/>  
    <kd value="10.0"/> 
  </gazebo>  
  <gazebo> 
    <plugin name="$(arg robot_name)_diff_drive" filename="libgazebo_ros_diff_drive.so"> 
      <ros> 
        <namespace>/$(arg robot_name)</namespace>  
        <remapping>cmd_vel:=cmd_vel</remapping>  
        <remapping>odom:=odom</remapping> 
      </ros>  
      <update_rate>60</update_rate>  
      <!-- wheels -->  
      <left_joint>$(arg robot_name)_left_wheel_joint</left_joint>  
      <right_joint>$(arg robot_name)_right_wheel_joint</right_joint>  
      <!-- kinematics -->  
      <wheel_separation>0.2</wheel_separation>  
      <wheel_diameter>0.065</wheel_diameter>  
      <!-- limits -->  
      <max_wheel_torque>20</max_wheel_torque>  
      <max_wheel_acceleration>1.0</max_wheel_acceleration>  
      <!-- output -->  
      <publish_odom>true</publish_odom>  
      <publish_odom_tf>false</publish_odom_tf>  
      <publish_wheel_tf>false</publish_wheel_tf>  
      <odometry_frame>$(arg robot_name)_odom</odometry_frame>  
      <robot_base_frame>$(arg robot_name)_base_footprint</robot_base_frame> 
    </plugin> 
  </gazebo>  
  <gazebo reference="$(arg robot_name)_imu_link"> 
    <sensor name="$(arg robot_name)_imu_sensor" type="imu"> 
      <plugin filename="libgazebo_ros_imu_sensor.so" name="imu_plugin"> 
        <ros> 
          <namespace>/$(arg robot_name)</namespace>  
          <remapping>~/out:=imu</remapping> 
        </ros>  
        <initial_orientation_as_reference>false</initial_orientation_as_reference> 
      </plugin>  
      <always_on>true</always_on>  
      <update_rate>100</update_rate>  
      <visualize>true</visualize>  
      <imu> 
        <angular_velocity> 
          <x> 
          </x>  
          <y> 
          </y>  
          <z> 
          </z> 
        </angular_velocity>  
        <linear_acceleration> 
          <x> 
          </x>  
          <y> 
          </y>  
          <z> 
          </z> 
        </linear_acceleration> 
      </imu> 
    </sensor> 
  </gazebo>  
  <gazebo reference="$(arg robot_name)_laser_link"> 
    <sensor name="$(arg robot_name)_laser_sensor" type="ray"> 
      <always_on>true</always_on>  
      <visualize>true</visualize>  
      <update_rate>50</update_rate>  
      <pose>0 0 0.075 0 0 0</pose>  
      <ray> 
        <scan> 
          <horizontal> 
            <samples>360</samples>  
            <resolution>1.000000</resolution>  
            <min_angle>-3.140000</min_angle>  
            <max_angle>3.140000</max_angle> 
          </horizontal> 
        </scan>  
        <range> 
          <min>0.10000</min>  
          <max>3.5</max>  
          <resolution>0.015000</resolution> 
        </range>  
      </ray>  
      <plugin name="$(arg robot_name)_laserscan" filename="libgazebo_ros_ray_sensor.so"> 
        <ros> 
          <namespace>/$(arg robot_name)</namespace>  
          <remapping>~/out:=scan</remapping> 
        </ros>  
        <output_type>sensor_msgs/LaserScan</output_type>  
        <frame_name>$(arg robot_name)_laser_link</frame_name> 
      </plugin> 
    </sensor> 
  </gazebo> 
</robot>